dispatcher.py [LINE:390] #ERROR    [2025-07-10 19:31:10,701]  Cause exception while getting updates.
Traceback (most recent call last):
  File "/home/mohirbek/Projects/tgbotmuvofiqiyat/venv310/lib/python3.10/site-packages/aiohttp/connector.py", line 1152, in _create_direct_connection
    hosts = await asyncio.shield(host_resolved)
  File "/home/mohirbek/Projects/tgbotmuvofiqiyat/venv310/lib/python3.10/site-packages/aiohttp/connector.py", line 874, in _resolve_host
    addrs = await self._resolver.resolve(host, port, family=self._family)
  File "/home/mohirbek/Projects/tgbotmuvofiqiyat/venv310/lib/python3.10/site-packages/aiohttp/resolver.py", line 33, in resolve
    infos = await self._loop.getaddrinfo(
  File "/usr/lib/python3.10/asyncio/base_events.py", line 863, in getaddrinfo
    return await self.run_in_executor(
  File "/usr/lib/python3.10/concurrent/futures/thread.py", line 58, in run
    result = self.fn(*self.args, **self.kwargs)
  File "/usr/lib/python3.10/socket.py", line 967, in getaddrinfo
    for res in _socket.getaddrinfo(host, port, family, type, proto, flags):
socket.gaierror: [Errno -3] Temporary failure in name resolution

The above exception was the direct cause of the following exception:

Traceback (most recent call last):
  File "/home/mohirbek/Projects/tgbotmuvofiqiyat/venv310/lib/python3.10/site-packages/aiogram/bot/api.py", line 139, in make_request
    async with session.post(url, data=req, **kwargs) as response:
  File "/home/mohirbek/Projects/tgbotmuvofiqiyat/venv310/lib/python3.10/site-packages/aiohttp/client.py", line 1141, in __aenter__
    self._resp = await self._coro
  File "/home/mohirbek/Projects/tgbotmuvofiqiyat/venv310/lib/python3.10/site-packages/aiohttp/client.py", line 536, in _request
    conn = await self._connector.connect(
  File "/home/mohirbek/Projects/tgbotmuvofiqiyat/venv310/lib/python3.10/site-packages/aiohttp/connector.py", line 540, in connect
    proto = await self._create_connection(req, traces, timeout)
  File "/home/mohirbek/Projects/tgbotmuvofiqiyat/venv310/lib/python3.10/site-packages/aiohttp/connector.py", line 901, in _create_connection
    _, proto = await self._create_direct_connection(req, traces, timeout)
  File "/home/mohirbek/Projects/tgbotmuvofiqiyat/venv310/lib/python3.10/site-packages/aiohttp/connector.py", line 1166, in _create_direct_connection
    raise ClientConnectorError(req.connection_key, exc) from exc
aiohttp.client_exceptions.ClientConnectorError: Cannot connect to host api.telegram.org:443 ssl:default [Temporary failure in name resolution]

During handling of the above exception, another exception occurred:

Traceback (most recent call last):
  File "/home/mohirbek/Projects/tgbotmuvofiqiyat/venv310/lib/python3.10/site-packages/aiogram/dispatcher/dispatcher.py", line 381, in start_polling
    updates = await self.bot.get_updates(
  File "/home/mohirbek/Projects/tgbotmuvofiqiyat/venv310/lib/python3.10/site-packages/aiogram/bot/bot.py", line 110, in get_updates
    result = await self.request(api.Methods.GET_UPDATES, payload)
  File "/home/mohirbek/Projects/tgbotmuvofiqiyat/venv310/lib/python3.10/site-packages/aiogram/bot/base.py", line 236, in request
    return await api.make_request(await self.get_session(), self.server, self.__token, method, data, files,
  File "/home/mohirbek/Projects/tgbotmuvofiqiyat/venv310/lib/python3.10/site-packages/aiogram/bot/api.py", line 142, in make_request
    raise exceptions.NetworkError(f"aiohttp client throws an error: {e.__class__.__name__}: {e}")
aiogram.utils.exceptions.NetworkError: Aiohttp client throws an error: ClientConnectorError: Cannot connect to host api.telegram.org:443 ssl:default [Temporary failure in name resolution]
