dispatcher.py [LINE:390] #ERROR    [2025-07-09 20:40:47,509]  Cause exception while getting updates.
Traceback (most recent call last):
  File "C:\Users\user\AppData\Local\Programs\Python\Python39\lib\site-packages\aiogram\dispatcher\dispatcher.py", line 381, in start_polling
    updates = await self.bot.get_updates(
  File "C:\Users\user\AppData\Local\Programs\Python\Python39\lib\site-packages\aiogram\bot\bot.py", line 110, in get_updates
    result = await self.request(api.Methods.GET_UPDATES, payload)
  File "C:\Users\user\AppData\Local\Programs\Python\Python39\lib\site-packages\aiogram\bot\base.py", line 236, in request
    return await api.make_request(await self.get_session(), self.server, self.__token, method, data, files,
  File "C:\Users\user\AppData\Local\Programs\Python\Python39\lib\site-packages\aiogram\bot\api.py", line 140, in make_request
    return check_result(method, response.content_type, response.status, await response.text())
  File "C:\Users\user\AppData\Local\Programs\Python\Python39\lib\site-packages\aiogram\bot\api.py", line 119, in check_result
    exceptions.ConflictError.detect(description)
  File "C:\Users\user\AppData\Local\Programs\Python\Python39\lib\site-packages\aiogram\utils\exceptions.py", line 140, in detect
    raise err(cls.text or description)
aiogram.utils.exceptions.TerminatedByOtherGetUpdates: Terminated by other getupdates request; make sure that only one bot instance is running
dispatcher.py [LINE:390] #ERROR    [2025-07-09 20:40:57,773]  Cause exception while getting updates.
Traceback (most recent call last):
  File "C:\Users\user\AppData\Local\Programs\Python\Python39\lib\site-packages\aiogram\dispatcher\dispatcher.py", line 381, in start_polling
    updates = await self.bot.get_updates(
  File "C:\Users\user\AppData\Local\Programs\Python\Python39\lib\site-packages\aiogram\bot\bot.py", line 110, in get_updates
    result = await self.request(api.Methods.GET_UPDATES, payload)
  File "C:\Users\user\AppData\Local\Programs\Python\Python39\lib\site-packages\aiogram\bot\base.py", line 236, in request
    return await api.make_request(await self.get_session(), self.server, self.__token, method, data, files,
  File "C:\Users\user\AppData\Local\Programs\Python\Python39\lib\site-packages\aiogram\bot\api.py", line 140, in make_request
    return check_result(method, response.content_type, response.status, await response.text())
  File "C:\Users\user\AppData\Local\Programs\Python\Python39\lib\site-packages\aiogram\bot\api.py", line 119, in check_result
    exceptions.ConflictError.detect(description)
  File "C:\Users\user\AppData\Local\Programs\Python\Python39\lib\site-packages\aiogram\utils\exceptions.py", line 140, in detect
    raise err(cls.text or description)
aiogram.utils.exceptions.TerminatedByOtherGetUpdates: Terminated by other getupdates request; make sure that only one bot instance is running
dispatcher.py [LINE:390] #ERROR    [2025-07-09 20:41:08,021]  Cause exception while getting updates.
Traceback (most recent call last):
  File "C:\Users\user\AppData\Local\Programs\Python\Python39\lib\site-packages\aiogram\dispatcher\dispatcher.py", line 381, in start_polling
    updates = await self.bot.get_updates(
  File "C:\Users\user\AppData\Local\Programs\Python\Python39\lib\site-packages\aiogram\bot\bot.py", line 110, in get_updates
    result = await self.request(api.Methods.GET_UPDATES, payload)
  File "C:\Users\user\AppData\Local\Programs\Python\Python39\lib\site-packages\aiogram\bot\base.py", line 236, in request
    return await api.make_request(await self.get_session(), self.server, self.__token, method, data, files,
  File "C:\Users\user\AppData\Local\Programs\Python\Python39\lib\site-packages\aiogram\bot\api.py", line 140, in make_request
    return check_result(method, response.content_type, response.status, await response.text())
  File "C:\Users\user\AppData\Local\Programs\Python\Python39\lib\site-packages\aiogram\bot\api.py", line 119, in check_result
    exceptions.ConflictError.detect(description)
  File "C:\Users\user\AppData\Local\Programs\Python\Python39\lib\site-packages\aiogram\utils\exceptions.py", line 140, in detect
    raise err(cls.text or description)
aiogram.utils.exceptions.TerminatedByOtherGetUpdates: Terminated by other getupdates request; make sure that only one bot instance is running
dispatcher.py [LINE:390] #ERROR    [2025-07-09 20:41:18,232]  Cause exception while getting updates.
Traceback (most recent call last):
  File "C:\Users\user\AppData\Local\Programs\Python\Python39\lib\site-packages\aiogram\dispatcher\dispatcher.py", line 381, in start_polling
    updates = await self.bot.get_updates(
  File "C:\Users\user\AppData\Local\Programs\Python\Python39\lib\site-packages\aiogram\bot\bot.py", line 110, in get_updates
    result = await self.request(api.Methods.GET_UPDATES, payload)
  File "C:\Users\user\AppData\Local\Programs\Python\Python39\lib\site-packages\aiogram\bot\base.py", line 236, in request
    return await api.make_request(await self.get_session(), self.server, self.__token, method, data, files,
  File "C:\Users\user\AppData\Local\Programs\Python\Python39\lib\site-packages\aiogram\bot\api.py", line 140, in make_request
    return check_result(method, response.content_type, response.status, await response.text())
  File "C:\Users\user\AppData\Local\Programs\Python\Python39\lib\site-packages\aiogram\bot\api.py", line 119, in check_result
    exceptions.ConflictError.detect(description)
  File "C:\Users\user\AppData\Local\Programs\Python\Python39\lib\site-packages\aiogram\utils\exceptions.py", line 140, in detect
    raise err(cls.text or description)
aiogram.utils.exceptions.TerminatedByOtherGetUpdates: Terminated by other getupdates request; make sure that only one bot instance is running
dispatcher.py [LINE:390] #ERROR    [2025-07-09 20:41:28,454]  Cause exception while getting updates.
Traceback (most recent call last):
  File "C:\Users\user\AppData\Local\Programs\Python\Python39\lib\site-packages\aiogram\dispatcher\dispatcher.py", line 381, in start_polling
    updates = await self.bot.get_updates(
  File "C:\Users\user\AppData\Local\Programs\Python\Python39\lib\site-packages\aiogram\bot\bot.py", line 110, in get_updates
    result = await self.request(api.Methods.GET_UPDATES, payload)
  File "C:\Users\user\AppData\Local\Programs\Python\Python39\lib\site-packages\aiogram\bot\base.py", line 236, in request
    return await api.make_request(await self.get_session(), self.server, self.__token, method, data, files,
  File "C:\Users\user\AppData\Local\Programs\Python\Python39\lib\site-packages\aiogram\bot\api.py", line 140, in make_request
    return check_result(method, response.content_type, response.status, await response.text())
  File "C:\Users\user\AppData\Local\Programs\Python\Python39\lib\site-packages\aiogram\bot\api.py", line 119, in check_result
    exceptions.ConflictError.detect(description)
  File "C:\Users\user\AppData\Local\Programs\Python\Python39\lib\site-packages\aiogram\utils\exceptions.py", line 140, in detect
    raise err(cls.text or description)
aiogram.utils.exceptions.TerminatedByOtherGetUpdates: Terminated by other getupdates request; make sure that only one bot instance is running
dispatcher.py [LINE:390] #ERROR    [2025-07-09 20:41:38,693]  Cause exception while getting updates.
Traceback (most recent call last):
  File "C:\Users\user\AppData\Local\Programs\Python\Python39\lib\site-packages\aiogram\dispatcher\dispatcher.py", line 381, in start_polling
    updates = await self.bot.get_updates(
  File "C:\Users\user\AppData\Local\Programs\Python\Python39\lib\site-packages\aiogram\bot\bot.py", line 110, in get_updates
    result = await self.request(api.Methods.GET_UPDATES, payload)
  File "C:\Users\user\AppData\Local\Programs\Python\Python39\lib\site-packages\aiogram\bot\base.py", line 236, in request
    return await api.make_request(await self.get_session(), self.server, self.__token, method, data, files,
  File "C:\Users\user\AppData\Local\Programs\Python\Python39\lib\site-packages\aiogram\bot\api.py", line 140, in make_request
    return check_result(method, response.content_type, response.status, await response.text())
  File "C:\Users\user\AppData\Local\Programs\Python\Python39\lib\site-packages\aiogram\bot\api.py", line 119, in check_result
    exceptions.ConflictError.detect(description)
  File "C:\Users\user\AppData\Local\Programs\Python\Python39\lib\site-packages\aiogram\utils\exceptions.py", line 140, in detect
    raise err(cls.text or description)
aiogram.utils.exceptions.TerminatedByOtherGetUpdates: Terminated by other getupdates request; make sure that only one bot instance is running
dispatcher.py [LINE:390] #ERROR    [2025-07-09 20:41:48,970]  Cause exception while getting updates.
Traceback (most recent call last):
  File "C:\Users\user\AppData\Local\Programs\Python\Python39\lib\site-packages\aiogram\dispatcher\dispatcher.py", line 381, in start_polling
    updates = await self.bot.get_updates(
  File "C:\Users\user\AppData\Local\Programs\Python\Python39\lib\site-packages\aiogram\bot\bot.py", line 110, in get_updates
    result = await self.request(api.Methods.GET_UPDATES, payload)
  File "C:\Users\user\AppData\Local\Programs\Python\Python39\lib\site-packages\aiogram\bot\base.py", line 236, in request
    return await api.make_request(await self.get_session(), self.server, self.__token, method, data, files,
  File "C:\Users\user\AppData\Local\Programs\Python\Python39\lib\site-packages\aiogram\bot\api.py", line 140, in make_request
    return check_result(method, response.content_type, response.status, await response.text())
  File "C:\Users\user\AppData\Local\Programs\Python\Python39\lib\site-packages\aiogram\bot\api.py", line 119, in check_result
    exceptions.ConflictError.detect(description)
  File "C:\Users\user\AppData\Local\Programs\Python\Python39\lib\site-packages\aiogram\utils\exceptions.py", line 140, in detect
    raise err(cls.text or description)
aiogram.utils.exceptions.TerminatedByOtherGetUpdates: Terminated by other getupdates request; make sure that only one bot instance is running
dispatcher.py [LINE:390] #ERROR    [2025-07-09 20:41:59,190]  Cause exception while getting updates.
Traceback (most recent call last):
  File "C:\Users\user\AppData\Local\Programs\Python\Python39\lib\site-packages\aiogram\dispatcher\dispatcher.py", line 381, in start_polling
    updates = await self.bot.get_updates(
  File "C:\Users\user\AppData\Local\Programs\Python\Python39\lib\site-packages\aiogram\bot\bot.py", line 110, in get_updates
    result = await self.request(api.Methods.GET_UPDATES, payload)
  File "C:\Users\user\AppData\Local\Programs\Python\Python39\lib\site-packages\aiogram\bot\base.py", line 236, in request
    return await api.make_request(await self.get_session(), self.server, self.__token, method, data, files,
  File "C:\Users\user\AppData\Local\Programs\Python\Python39\lib\site-packages\aiogram\bot\api.py", line 140, in make_request
    return check_result(method, response.content_type, response.status, await response.text())
  File "C:\Users\user\AppData\Local\Programs\Python\Python39\lib\site-packages\aiogram\bot\api.py", line 119, in check_result
    exceptions.ConflictError.detect(description)
  File "C:\Users\user\AppData\Local\Programs\Python\Python39\lib\site-packages\aiogram\utils\exceptions.py", line 140, in detect
    raise err(cls.text or description)
aiogram.utils.exceptions.TerminatedByOtherGetUpdates: Terminated by other getupdates request; make sure that only one bot instance is running
dispatcher.py [LINE:390] #ERROR    [2025-07-09 20:42:50,821]  Cause exception while getting updates.
Traceback (most recent call last):
  File "C:\Users\user\AppData\Local\Programs\Python\Python39\lib\site-packages\aiogram\dispatcher\dispatcher.py", line 381, in start_polling
    updates = await self.bot.get_updates(
  File "C:\Users\user\AppData\Local\Programs\Python\Python39\lib\site-packages\aiogram\bot\bot.py", line 110, in get_updates
    result = await self.request(api.Methods.GET_UPDATES, payload)
  File "C:\Users\user\AppData\Local\Programs\Python\Python39\lib\site-packages\aiogram\bot\base.py", line 236, in request
    return await api.make_request(await self.get_session(), self.server, self.__token, method, data, files,
  File "C:\Users\user\AppData\Local\Programs\Python\Python39\lib\site-packages\aiogram\bot\api.py", line 140, in make_request
    return check_result(method, response.content_type, response.status, await response.text())
  File "C:\Users\user\AppData\Local\Programs\Python\Python39\lib\site-packages\aiogram\bot\api.py", line 119, in check_result
    exceptions.ConflictError.detect(description)
  File "C:\Users\user\AppData\Local\Programs\Python\Python39\lib\site-packages\aiogram\utils\exceptions.py", line 140, in detect
    raise err(cls.text or description)
aiogram.utils.exceptions.TerminatedByOtherGetUpdates: Terminated by other getupdates request; make sure that only one bot instance is running
