dispatcher.py [LINE:390] #ERROR    [2025-07-10 18:34:48,642]  Cause exception while getting updates.
Traceback (most recent call last):
  File "/home/mohirbek/Projects/tgbotmuvofiqiyat/venv310/lib/python3.10/site-packages/aiogram/dispatcher/dispatcher.py", line 381, in start_polling
    updates = await self.bot.get_updates(
  File "/home/mohirbek/Projects/tgbotmuvofiqiyat/venv310/lib/python3.10/site-packages/aiogram/bot/bot.py", line 110, in get_updates
    result = await self.request(api.Methods.GET_UPDATES, payload)
  File "/home/mohirbek/Projects/tgbotmuvofiqiyat/venv310/lib/python3.10/site-packages/aiogram/bot/base.py", line 236, in request
    return await api.make_request(await self.get_session(), self.server, self.__token, method, data, files,
  File "/home/mohirbek/Projects/tgbotmuvofiqiyat/venv310/lib/python3.10/site-packages/aiogram/bot/api.py", line 140, in make_request
    return check_result(method, response.content_type, response.status, await response.text())
  File "/home/mohirbek/Projects/tgbotmuvofiqiyat/venv310/lib/python3.10/site-packages/aiogram/bot/api.py", line 119, in check_result
    exceptions.ConflictError.detect(description)
  File "/home/mohirbek/Projects/tgbotmuvofiqiyat/venv310/lib/python3.10/site-packages/aiogram/utils/exceptions.py", line 140, in detect
    raise err(cls.text or description)
aiogram.utils.exceptions.TerminatedByOtherGetUpdates: Terminated by other getupdates request; make sure that only one bot instance is running
dispatcher.py [LINE:390] #ERROR    [2025-07-10 18:34:58,807]  Cause exception while getting updates.
Traceback (most recent call last):
  File "/home/mohirbek/Projects/tgbotmuvofiqiyat/venv310/lib/python3.10/site-packages/aiogram/dispatcher/dispatcher.py", line 381, in start_polling
    updates = await self.bot.get_updates(
  File "/home/mohirbek/Projects/tgbotmuvofiqiyat/venv310/lib/python3.10/site-packages/aiogram/bot/bot.py", line 110, in get_updates
    result = await self.request(api.Methods.GET_UPDATES, payload)
  File "/home/mohirbek/Projects/tgbotmuvofiqiyat/venv310/lib/python3.10/site-packages/aiogram/bot/base.py", line 236, in request
    return await api.make_request(await self.get_session(), self.server, self.__token, method, data, files,
  File "/home/mohirbek/Projects/tgbotmuvofiqiyat/venv310/lib/python3.10/site-packages/aiogram/bot/api.py", line 140, in make_request
    return check_result(method, response.content_type, response.status, await response.text())
  File "/home/mohirbek/Projects/tgbotmuvofiqiyat/venv310/lib/python3.10/site-packages/aiogram/bot/api.py", line 119, in check_result
    exceptions.ConflictError.detect(description)
  File "/home/mohirbek/Projects/tgbotmuvofiqiyat/venv310/lib/python3.10/site-packages/aiogram/utils/exceptions.py", line 140, in detect
    raise err(cls.text or description)
aiogram.utils.exceptions.TerminatedByOtherGetUpdates: Terminated by other getupdates request; make sure that only one bot instance is running
dispatcher.py [LINE:390] #ERROR    [2025-07-10 18:35:55,707]  Cause exception while getting updates.
Traceback (most recent call last):
  File "/home/mohirbek/Projects/tgbotmuvofiqiyat/venv310/lib/python3.10/site-packages/aiogram/dispatcher/dispatcher.py", line 381, in start_polling
    updates = await self.bot.get_updates(
  File "/home/mohirbek/Projects/tgbotmuvofiqiyat/venv310/lib/python3.10/site-packages/aiogram/bot/bot.py", line 110, in get_updates
    result = await self.request(api.Methods.GET_UPDATES, payload)
  File "/home/mohirbek/Projects/tgbotmuvofiqiyat/venv310/lib/python3.10/site-packages/aiogram/bot/base.py", line 236, in request
    return await api.make_request(await self.get_session(), self.server, self.__token, method, data, files,
  File "/home/mohirbek/Projects/tgbotmuvofiqiyat/venv310/lib/python3.10/site-packages/aiogram/bot/api.py", line 140, in make_request
    return check_result(method, response.content_type, response.status, await response.text())
  File "/home/mohirbek/Projects/tgbotmuvofiqiyat/venv310/lib/python3.10/site-packages/aiogram/bot/api.py", line 119, in check_result
    exceptions.ConflictError.detect(description)
  File "/home/mohirbek/Projects/tgbotmuvofiqiyat/venv310/lib/python3.10/site-packages/aiogram/utils/exceptions.py", line 140, in detect
    raise err(cls.text or description)
aiogram.utils.exceptions.TerminatedByOtherGetUpdates: Terminated by other getupdates request; make sure that only one bot instance is running
dispatcher.py [LINE:390] #ERROR    [2025-07-10 18:36:08,725]  Cause exception while getting updates.
Traceback (most recent call last):
  File "/home/mohirbek/Projects/tgbotmuvofiqiyat/venv310/lib/python3.10/site-packages/aiogram/dispatcher/dispatcher.py", line 381, in start_polling
    updates = await self.bot.get_updates(
  File "/home/mohirbek/Projects/tgbotmuvofiqiyat/venv310/lib/python3.10/site-packages/aiogram/bot/bot.py", line 110, in get_updates
    result = await self.request(api.Methods.GET_UPDATES, payload)
  File "/home/mohirbek/Projects/tgbotmuvofiqiyat/venv310/lib/python3.10/site-packages/aiogram/bot/base.py", line 236, in request
    return await api.make_request(await self.get_session(), self.server, self.__token, method, data, files,
  File "/home/mohirbek/Projects/tgbotmuvofiqiyat/venv310/lib/python3.10/site-packages/aiogram/bot/api.py", line 140, in make_request
    return check_result(method, response.content_type, response.status, await response.text())
  File "/home/mohirbek/Projects/tgbotmuvofiqiyat/venv310/lib/python3.10/site-packages/aiogram/bot/api.py", line 119, in check_result
    exceptions.ConflictError.detect(description)
  File "/home/mohirbek/Projects/tgbotmuvofiqiyat/venv310/lib/python3.10/site-packages/aiogram/utils/exceptions.py", line 140, in detect
    raise err(cls.text or description)
aiogram.utils.exceptions.TerminatedByOtherGetUpdates: Terminated by other getupdates request; make sure that only one bot instance is running
